Traceback (most recent call last):
  File "C:\Users\jqbon\anaconda3\Lib\site-packages\jupyter_cache\executors\utils.py", line 58, in single_nb_execution
    executenb(
  File "C:\Users\jqbon\anaconda3\Lib\site-packages\nbclient\client.py", line 1305, in execute
    return NotebookClient(nb=nb, resources=resources, km=km, **kwargs).execute()
           ^^^^^^^^^^^^^^^^^^^^^^^^^^^^^^^^^^^^^^^^^^^^^^^^^^^^^^^^^^^^^^^^^^^^^
  File "C:\Users\jqbon\anaconda3\Lib\site-packages\jupyter_core\utils\__init__.py", line 165, in wrapped
    return loop.run_until_complete(inner)
           ^^^^^^^^^^^^^^^^^^^^^^^^^^^^^^
  File "C:\Users\jqbon\anaconda3\Lib\asyncio\base_events.py", line 687, in run_until_complete
    return future.result()
           ^^^^^^^^^^^^^^^
  File "C:\Users\jqbon\anaconda3\Lib\site-packages\nbclient\client.py", line 705, in async_execute
    await self.async_execute_cell(
  File "C:\Users\jqbon\anaconda3\Lib\site-packages\nbclient\client.py", line 1058, in async_execute_cell
    await self._check_raise_for_error(cell, cell_index, exec_reply)
  File "C:\Users\jqbon\anaconda3\Lib\site-packages\nbclient\client.py", line 914, in _check_raise_for_error
    raise CellExecutionError.from_cell_and_msg(cell, exec_reply_content)
nbclient.exceptions.CellExecutionError: An error occurred while executing the following cell:
------------------
opt.newton(g, 5/9, fprime = dg)
------------------


[1;31m---------------------------------------------------------------------------[0m
[1;31mRuntimeError[0m                              Traceback (most recent call last)
Cell [1;32mIn[20], line 1[0m
[1;32m----> 1[0m opt[38;5;241m.[39mnewton(g, [38;5;241m5[39m[38;5;241m/[39m[38;5;241m9[39m, fprime [38;5;241m=[39m dg)

File [1;32m~\anaconda3\Lib\site-packages\scipy\optimize\_zeros_py.py:391[0m, in [0;36mnewton[1;34m(func, x0, fprime, args, tol, maxiter, fprime2, x1, rtol, full_output, disp)[0m
[0;32m    388[0m [38;5;28;01mif[39;00m disp:
[0;32m    389[0m     msg [38;5;241m=[39m ([38;5;124m"[39m[38;5;124mFailed to converge after [39m[38;5;132;01m%d[39;00m[38;5;124m iterations, value is [39m[38;5;132;01m%s[39;00m[38;5;124m.[39m[38;5;124m"[39m
[0;32m    390[0m            [38;5;241m%[39m (itr [38;5;241m+[39m [38;5;241m1[39m, p))
[1;32m--> 391[0m     [38;5;28;01mraise[39;00m [38;5;167;01mRuntimeError[39;00m(msg)
[0;32m    393[0m [38;5;28;01mreturn[39;00m _results_select(full_output, (p, funcalls, itr [38;5;241m+[39m [38;5;241m1[39m, _ECONVERR), method)

[1;31mRuntimeError[0m: Failed to converge after 50 iterations, value is 0.8467420063356614.

