Traceback (most recent call last):
  File "C:\Users\jqbond\AppData\Roaming\Python\Python39\site-packages\jupyter_cache\executors\utils.py", line 51, in single_nb_execution
    executenb(
  File "C:\Users\jqbond\AppData\Roaming\Python\Python39\site-packages\nbclient\client.py", line 1204, in execute
    return NotebookClient(nb=nb, resources=resources, km=km, **kwargs).execute()
  File "C:\Users\jqbond\AppData\Roaming\Python\Python39\site-packages\nbclient\util.py", line 84, in wrapped
    return just_run(coro(*args, **kwargs))
  File "C:\Users\jqbond\AppData\Roaming\Python\Python39\site-packages\nbclient\util.py", line 62, in just_run
    return loop.run_until_complete(coro)
  File "C:\Users\jqbond\anaconda3\lib\asyncio\base_events.py", line 647, in run_until_complete
    return future.result()
  File "C:\Users\jqbond\AppData\Roaming\Python\Python39\site-packages\nbclient\client.py", line 663, in async_execute
    await self.async_execute_cell(
  File "C:\Users\jqbond\AppData\Roaming\Python\Python39\site-packages\nbclient\client.py", line 965, in async_execute_cell
    await self._check_raise_for_error(cell, cell_index, exec_reply)
  File "C:\Users\jqbond\AppData\Roaming\Python\Python39\site-packages\nbclient\client.py", line 862, in _check_raise_for_error
    raise CellExecutionError.from_cell_and_msg(cell, exec_reply_content)
nbclient.exceptions.CellExecutionError: An error occurred while executing the following cell:
------------------
import csv

#Load Experimental Times; convert to 1D numpy array
file = open("t1.csv") #experimental times in minutes
csvreader = csv.reader(file)
rows = []
for row in csvreader:
     rows.append(row)
file.close()
print(np.array(rows, dtype = 'float').shape)
t1 = np.array(rows, dtype = 'float').reshape(len(rows), )
print(t1.shape)

#Load Experimental Concentrations; convert to 1D numpy array
file = open("C1.csv")
csvreader = csv.reader(file)
rows = []
for row in csvreader:
     rows.append(row)
file.close()
print(np.array(rows, dtype = 'float').shape)
C1 = np.array(rows, dtype = 'float').reshape(len(rows), )
print(C1.shape)
------------------

[1;31m---------------------------------------------------------------------------[0m
[1;31mFileNotFoundError[0m                         Traceback (most recent call last)
[1;32m~\AppData\Local\Temp\ipykernel_1168\927930801.py[0m in [0;36m<cell line: 4>[1;34m()[0m
[0;32m      2[0m [1;33m[0m[0m
[0;32m      3[0m [1;31m#Load Experimental Times; convert to 1D numpy array[0m[1;33m[0m[1;33m[0m[0m
[1;32m----> 4[1;33m [0mfile[0m [1;33m=[0m [0mopen[0m[1;33m([0m[1;34m"t1.csv"[0m[1;33m)[0m [1;31m#experimental times in minutes[0m[1;33m[0m[1;33m[0m[0m
[0m[0;32m      5[0m [0mcsvreader[0m [1;33m=[0m [0mcsv[0m[1;33m.[0m[0mreader[0m[1;33m([0m[0mfile[0m[1;33m)[0m[1;33m[0m[1;33m[0m[0m
[0;32m      6[0m [0mrows[0m [1;33m=[0m [1;33m[[0m[1;33m][0m[1;33m[0m[1;33m[0m[0m

[1;31mFileNotFoundError[0m: [Errno 2] No such file or directory: 't1.csv'
FileNotFoundError: [Errno 2] No such file or directory: 't1.csv'

