Traceback (most recent call last):
  File "C:\Users\jqbond\AppData\Roaming\Python\Python39\site-packages\jupyter_cache\executors\utils.py", line 51, in single_nb_execution
    executenb(
  File "C:\Users\jqbond\AppData\Roaming\Python\Python39\site-packages\nbclient\client.py", line 1204, in execute
    return NotebookClient(nb=nb, resources=resources, km=km, **kwargs).execute()
  File "C:\Users\jqbond\AppData\Roaming\Python\Python39\site-packages\nbclient\util.py", line 84, in wrapped
    return just_run(coro(*args, **kwargs))
  File "C:\Users\jqbond\AppData\Roaming\Python\Python39\site-packages\nbclient\util.py", line 62, in just_run
    return loop.run_until_complete(coro)
  File "C:\Users\jqbond\anaconda3\lib\asyncio\base_events.py", line 647, in run_until_complete
    return future.result()
  File "C:\Users\jqbond\AppData\Roaming\Python\Python39\site-packages\nbclient\client.py", line 663, in async_execute
    await self.async_execute_cell(
  File "C:\Users\jqbond\AppData\Roaming\Python\Python39\site-packages\nbclient\client.py", line 965, in async_execute_cell
    await self._check_raise_for_error(cell, cell_index, exec_reply)
  File "C:\Users\jqbond\AppData\Roaming\Python\Python39\site-packages\nbclient\client.py", line 862, in _check_raise_for_error
    raise CellExecutionError.from_cell_and_msg(cell, exec_reply_content)
nbclient.exceptions.CellExecutionError: An error occurred while executing the following cell:
------------------
opt.newton(g, 5/9, fprime = dg)
------------------

[1;31m---------------------------------------------------------------------------[0m
[1;31mRuntimeError[0m                              Traceback (most recent call last)
[1;32m~\AppData\Local\Temp\ipykernel_11420\2397142780.py[0m in [0;36m<cell line: 1>[1;34m()[0m
[1;32m----> 1[1;33m [0mopt[0m[1;33m.[0m[0mnewton[0m[1;33m([0m[0mg[0m[1;33m,[0m [1;36m5[0m[1;33m/[0m[1;36m9[0m[1;33m,[0m [0mfprime[0m [1;33m=[0m [0mdg[0m[1;33m)[0m[1;33m[0m[1;33m[0m[0m
[0m
[1;32m~\anaconda3\lib\site-packages\scipy\optimize\_zeros_py.py[0m in [0;36mnewton[1;34m(func, x0, fprime, args, tol, maxiter, fprime2, x1, rtol, full_output, disp)[0m
[0;32m    366[0m         msg = ("Failed to converge after %d iterations, value is %s."
[0;32m    367[0m                % (itr + 1, p))
[1;32m--> 368[1;33m         [1;32mraise[0m [0mRuntimeError[0m[1;33m([0m[0mmsg[0m[1;33m)[0m[1;33m[0m[1;33m[0m[0m
[0m[0;32m    369[0m [1;33m[0m[0m
[0;32m    370[0m     [1;32mreturn[0m [0m_results_select[0m[1;33m([0m[0mfull_output[0m[1;33m,[0m [1;33m([0m[0mp[0m[1;33m,[0m [0mfuncalls[0m[1;33m,[0m [0mitr[0m [1;33m+[0m [1;36m1[0m[1;33m,[0m [0m_ECONVERR[0m[1;33m)[0m[1;33m)[0m[1;33m[0m[1;33m[0m[0m

[1;31mRuntimeError[0m: Failed to converge after 50 iterations, value is 0.8467420063356614.
RuntimeError: Failed to converge after 50 iterations, value is 0.8467420063356614.

