Traceback (most recent call last):
  File "C:\Users\jqbond\AppData\Roaming\Python\Python39\site-packages\jupyter_cache\executors\utils.py", line 51, in single_nb_execution
    executenb(
  File "C:\Users\jqbond\AppData\Roaming\Python\Python39\site-packages\nbclient\client.py", line 1204, in execute
    return NotebookClient(nb=nb, resources=resources, km=km, **kwargs).execute()
  File "C:\Users\jqbond\AppData\Roaming\Python\Python39\site-packages\nbclient\util.py", line 84, in wrapped
    return just_run(coro(*args, **kwargs))
  File "C:\Users\jqbond\AppData\Roaming\Python\Python39\site-packages\nbclient\util.py", line 62, in just_run
    return loop.run_until_complete(coro)
  File "C:\Users\jqbond\anaconda3\lib\asyncio\base_events.py", line 647, in run_until_complete
    return future.result()
  File "C:\Users\jqbond\AppData\Roaming\Python\Python39\site-packages\nbclient\client.py", line 663, in async_execute
    await self.async_execute_cell(
  File "C:\Users\jqbond\AppData\Roaming\Python\Python39\site-packages\nbclient\client.py", line 965, in async_execute_cell
    await self._check_raise_for_error(cell, cell_index, exec_reply)
  File "C:\Users\jqbond\AppData\Roaming\Python\Python39\site-packages\nbclient\client.py", line 862, in _check_raise_for_error
    raise CellExecutionError.from_cell_and_msg(cell, exec_reply_content)
nbclient.exceptions.CellExecutionError: An error occurred while executing the following cell:
------------------
#Load Experimental Times; convert to 1D numpy array
file = open("DATA1.csv")
csvreader = csv.reader(file)
rows = []
for row in csvreader:
     rows.append(row)
file.close()
DATA1 = np.array(rows, dtype = 'float')

labels = ['CAf (mol/L)', 'CBf (mol/L)', 'T (K)', 'r (mol/L/min)']
df = pd.DataFrame(DATA1, columns = labels)
#display(df)

EXP1  = DATA1[0:17, :]
EXP2  = DATA1[17:,:]

CA1  = EXP1[:,0]
CB1  = EXP1[:,1]
T1   = EXP1[:,2]
r1   = EXP1[:,3]

CA2  = EXP2[:,0]
CB2  = EXP2[:,1]
T2   = EXP2[:,2]
r2   = EXP2[:,3]
------------------

[1;31m---------------------------------------------------------------------------[0m
[1;31mFileNotFoundError[0m                         Traceback (most recent call last)
[1;32m~\AppData\Local\Temp\ipykernel_18656\2690256211.py[0m in [0;36m<cell line: 2>[1;34m()[0m
[0;32m      1[0m [1;31m#Load Experimental Times; convert to 1D numpy array[0m[1;33m[0m[1;33m[0m[0m
[1;32m----> 2[1;33m [0mfile[0m [1;33m=[0m [0mopen[0m[1;33m([0m[1;34m"DATA1.csv"[0m[1;33m)[0m[1;33m[0m[1;33m[0m[0m
[0m[0;32m      3[0m [0mcsvreader[0m [1;33m=[0m [0mcsv[0m[1;33m.[0m[0mreader[0m[1;33m([0m[0mfile[0m[1;33m)[0m[1;33m[0m[1;33m[0m[0m
[0;32m      4[0m [0mrows[0m [1;33m=[0m [1;33m[[0m[1;33m][0m[1;33m[0m[1;33m[0m[0m
[0;32m      5[0m [1;32mfor[0m [0mrow[0m [1;32min[0m [0mcsvreader[0m[1;33m:[0m[1;33m[0m[1;33m[0m[0m

[1;31mFileNotFoundError[0m: [Errno 2] No such file or directory: 'DATA1.csv'
FileNotFoundError: [Errno 2] No such file or directory: 'DATA1.csv'

