Traceback (most recent call last):
  File "C:\Users\Jesse Bond\AppData\Local\anaconda3\lib\site-packages\jupyter_cache\executors\utils.py", line 58, in single_nb_execution
    executenb(
  File "C:\Users\Jesse Bond\AppData\Local\anaconda3\lib\site-packages\nbclient\client.py", line 1204, in execute
    return NotebookClient(nb=nb, resources=resources, km=km, **kwargs).execute()
  File "C:\Users\Jesse Bond\AppData\Local\anaconda3\lib\site-packages\nbclient\util.py", line 84, in wrapped
    return just_run(coro(*args, **kwargs))
  File "C:\Users\Jesse Bond\AppData\Local\anaconda3\lib\site-packages\nbclient\util.py", line 62, in just_run
    return loop.run_until_complete(coro)
  File "C:\Users\Jesse Bond\AppData\Local\anaconda3\lib\asyncio\base_events.py", line 649, in run_until_complete
    return future.result()
  File "C:\Users\Jesse Bond\AppData\Local\anaconda3\lib\site-packages\nbclient\client.py", line 663, in async_execute
    await self.async_execute_cell(
  File "C:\Users\Jesse Bond\AppData\Local\anaconda3\lib\site-packages\nbclient\client.py", line 965, in async_execute_cell
    await self._check_raise_for_error(cell, cell_index, exec_reply)
  File "C:\Users\Jesse Bond\AppData\Local\anaconda3\lib\site-packages\nbclient\client.py", line 862, in _check_raise_for_error
    raise CellExecutionError.from_cell_and_msg(cell, exec_reply_content)
nbclient.exceptions.CellExecutionError: An error occurred while executing the following cell:
------------------
FAf = FA1 #mol/min
FBf = 0.0
FCf = 0.0
Vspan = (0.0, 1000.0)
var0  = (FAf, FBf, FCf)
par0  = (kf, kr, T, P, R)
ans2  = solve_ivp(P01, Vspan, var0, args = (par0, ), atol = 1e-8, rtol =  1e-8)

V     = ans2.t
FA    = ans2.y[0, :]
FB    = ans2.y[1, :]
FC    = ans2.y[2, :]

XA    = (FAf - FA)/FAf

plt.figure(1, figsize = (5, 5))
plt.plot(V, XA)
plt.xlim(0.0, max(Vspan))
plt.xticks(fontsize = 11)
plt.xlabel('Volume (L)', fontsize = 14)
plt.ylim(0.0, 1.0)
plt.yticks(fontsize = 11)
plt.ylabel('Conversion of A', fontsize = 14)
plt.show(1)

itp1 = interp1d(XA, V)
print(f'The Volume required for a PFR single pass conversion of XA = {XSP:0.4f} is {itp1(XSP):0.0f}L')
------------------

[1;31m---------------------------------------------------------------------------[0m
[1;31mValueError[0m                                Traceback (most recent call last)
Cell [1;32mIn[5], line 27[0m
[0;32m     24[0m plt[38;5;241m.[39mshow([38;5;241m1[39m)
[0;32m     26[0m itp1 [38;5;241m=[39m interp1d(XA, V)
[1;32m---> 27[0m [38;5;28mprint[39m([38;5;124mf[39m[38;5;124m'[39m[38;5;124mThe Volume required for a PFR single pass conversion of XA = [39m[38;5;132;01m{[39;00mXSP[38;5;132;01m:[39;00m[38;5;124m0.4f[39m[38;5;132;01m}[39;00m[38;5;124m is [39m[38;5;132;01m{[39;00mitp1(XSP)[38;5;132;01m:[39;00m[38;5;124m0.0f[39m[38;5;132;01m}[39;00m[38;5;124mL[39m[38;5;124m'[39m)

File [1;32m~\AppData\Local\anaconda3\lib\site-packages\scipy\interpolate\_polyint.py:80[0m, in [0;36m_Interpolator1D.__call__[1;34m(self, x)[0m
[0;32m     59[0m [38;5;250m[39m[38;5;124;03m"""[39;00m
[0;32m     60[0m [38;5;124;03mEvaluate the interpolant[39;00m
[0;32m     61[0m 
[1;32m   (...)[0m
[0;32m     77[0m 
[0;32m     78[0m [38;5;124;03m"""[39;00m
[0;32m     79[0m x, x_shape [38;5;241m=[39m [38;5;28mself[39m[38;5;241m.[39m_prepare_x(x)
[1;32m---> 80[0m y [38;5;241m=[39m [38;5;28;43mself[39;49m[38;5;241;43m.[39;49m[43m_evaluate[49m[43m([49m[43mx[49m[43m)[49m
[0;32m     81[0m [38;5;28;01mreturn[39;00m [38;5;28mself[39m[38;5;241m.[39m_finish_y(y, x_shape)

File [1;32m~\AppData\Local\anaconda3\lib\site-packages\scipy\interpolate\_interpolate.py:755[0m, in [0;36minterp1d._evaluate[1;34m(self, x_new)[0m
[0;32m    753[0m y_new [38;5;241m=[39m [38;5;28mself[39m[38;5;241m.[39m_call([38;5;28mself[39m, x_new)
[0;32m    754[0m [38;5;28;01mif[39;00m [38;5;129;01mnot[39;00m [38;5;28mself[39m[38;5;241m.[39m_extrapolate:
[1;32m--> 755[0m     below_bounds, above_bounds [38;5;241m=[39m [38;5;28;43mself[39;49m[38;5;241;43m.[39;49m[43m_check_bounds[49m[43m([49m[43mx_new[49m[43m)[49m
[0;32m    756[0m     [38;5;28;01mif[39;00m [38;5;28mlen[39m(y_new) [38;5;241m>[39m [38;5;241m0[39m:
[0;32m    757[0m         [38;5;66;03m# Note fill_value must be broadcast up to the proper size[39;00m
[0;32m    758[0m         [38;5;66;03m# and flattened to work here[39;00m
[0;32m    759[0m         y_new[below_bounds] [38;5;241m=[39m [38;5;28mself[39m[38;5;241m.[39m_fill_value_below

File [1;32m~\AppData\Local\anaconda3\lib\site-packages\scipy\interpolate\_interpolate.py:789[0m, in [0;36minterp1d._check_bounds[1;34m(self, x_new)[0m
[0;32m    787[0m [38;5;28;01mif[39;00m [38;5;28mself[39m[38;5;241m.[39mbounds_error [38;5;129;01mand[39;00m above_bounds[38;5;241m.[39many():
[0;32m    788[0m     above_bounds_value [38;5;241m=[39m x_new[np[38;5;241m.[39margmax(above_bounds)]
[1;32m--> 789[0m     [38;5;28;01mraise[39;00m [38;5;167;01mValueError[39;00m([38;5;124m"[39m[38;5;124mA value ([39m[38;5;132;01m{}[39;00m[38;5;124m) in x_new is above [39m[38;5;124m"[39m
[0;32m    790[0m                      [38;5;124m"[39m[38;5;124mthe interpolation range[39m[38;5;124m'[39m[38;5;124ms maximum value ([39m[38;5;132;01m{}[39;00m[38;5;124m).[39m[38;5;124m"[39m
[0;32m    791[0m                      [38;5;241m.[39mformat(above_bounds_value, [38;5;28mself[39m[38;5;241m.[39mx[[38;5;241m-[39m[38;5;241m1[39m]))
[0;32m    793[0m [38;5;66;03m# !! Should we emit a warning if some values are out of bounds?[39;00m
[0;32m    794[0m [38;5;66;03m# !! matlab does not.[39;00m
[0;32m    795[0m [38;5;28;01mreturn[39;00m below_bounds, above_bounds

[1;31mValueError[0m: A value (0.95) in x_new is above the interpolation range's maximum value (0.4473444481820728).
ValueError: A value (0.95) in x_new is above the interpolation range's maximum value (0.4473444481820728).

